<?xml version="1.0"?>
<robot xmlns:xacro="http://ros.org/wiki/xacro">
    <xacro:macro name="actuator_joint" params="name parent child">
        <joint name="${name}" type="revolute">
            <parent link="${parent}"/>
            <child link="${child}"/>
            <axis xyz="0 1 0"/>
            <limit lower="-1.57" upper="1.57" effort="1000" velocity="1.5"/>
            <!-- Adjust the limit, effort, and velocity according to the actuator's specifications -->
        </joint>
    </xacro:macro>
</robot>
