<?xml version="1.0" ?><robot name="armbot">  
  <link name="base_link">    
    <visual>      
      <origin xyz="-1.4954010252310467877e-12 0.062950280607105862929 -0.014800447380542768733" rpy="-3.141592653589793116 6.1629758220391415926e-32 1.3684555315672011322e-48"/>      
      <geometry>        
        <mesh filename="package://armbot_description/onshape_to_robot/armbot/hebirotor2020.stl"/>        
      </geometry>      
      <material name="hebirotor2020_material">        
        <color rgba="0.97254901960784312376 0.78039215686274510109 0.82352941176470584317 1.0"/>        
      </material>      
    </visual>    
    <collision>      
      <origin xyz="-1.4954010252310467877e-12 0.062950280607105862929 -0.014800447380542768733" rpy="-3.141592653589793116 6.1629758220391415926e-32 1.3684555315672011322e-48"/>      
      <geometry>        
        <mesh filename="package://armbot_description/onshape_to_robot/armbot/hebirotor2020.stl"/>        
      </geometry>      
    </collision>    
    <visual>      
      <origin xyz="0.02888621348162832142 0.062950280607105835173 -0.040500447380543133646" rpy="-1.57079632679489678 -1.570796326794896336 0"/>      
      <geometry>        
        <mesh filename="package://armbot_description/onshape_to_robot/armbot/2040_t-slot_(1ft).stl"/>        
      </geometry>      
      <material name="2040_t-slot_(1ft)_material">        
        <color rgba="0.90196078431372550543 0.90196078431372550543 0.90196078431372550543 1.0"/>        
      </material>      
    </visual>    
    <collision>      
      <origin xyz="0.02888621348162832142 0.062950280607105835173 -0.040500447380543133646" rpy="-1.57079632679489678 -1.570796326794896336 0"/>      
      <geometry>        
        <mesh filename="package://armbot_description/onshape_to_robot/armbot/2040_t-slot_(1ft).stl"/>        
      </geometry>      
    </collision>    
    <visual>      
      <origin xyz="0.094606904865056795639 0.062950280607105821296 -0.040500447380543203035" rpy="-1.570796326794896558 3.2583014967480242975e-16 -3.1123027901511928614e-31"/>      
      <geometry>        
        <mesh filename="package://armbot_description/onshape_to_robot/armbot/2020_t-slot_(1ft).stl"/>        
      </geometry>      
      <material name="2020_t-slot_(1ft)_material">        
        <color rgba="0.90196078431372550543 0.90196078431372550543 0.90196078431372550543 1.0"/>        
      </material>      
    </visual>    
    <collision>      
      <origin xyz="0.094606904865056795639 0.062950280607105821296 -0.040500447380543203035" rpy="-1.570796326794896558 3.2583014967480242975e-16 -3.1123027901511928614e-31"/>      
      <geometry>        
        <mesh filename="package://armbot_description/onshape_to_robot/armbot/2020_t-slot_(1ft).stl"/>        
      </geometry>      
    </collision>    
    <inertial>      
      <origin xyz="0.041789958961146948802 0.062950316529327587922 -0.037021889360947163317" rpy="0 0 0"/>      
      <mass value="0.50661056717106101033"/>      
      <inertia ixx="0.0031380149866881684034" ixy="1.476597618298327554e-09" ixz="7.3642275632454710335e-05" iyy="0.0010511859547597036425" iyz="-2.8921384746595283579e-10" izz="0.0041090667774130451573"/>      
    </inertial>    
  </link>  
  <link name="2040_t-slot_(1ft)">    
    <visual>      
      <origin xyz="0.016587994231491095393 -2.7755575615628913511e-17 -0.010000000000000005412" rpy="-1.570796326794896558 -1.570796326794896336 0"/>      
      <geometry>        
        <mesh filename="package://armbot_description/onshape_to_robot/armbot/2040_t-slot_(1ft).stl"/>        
      </geometry>      
      <material name="2040_t-slot_(1ft)_material">        
        <color rgba="0.90196078431372550543 0.90196078431372550543 0.90196078431372550543 1.0"/>        
      </material>      
    </visual>    
    <collision>      
      <origin xyz="0.016587994231491095393 -2.7755575615628913511e-17 -0.010000000000000005412" rpy="-1.570796326794896558 -1.570796326794896336 0"/>      
      <geometry>        
        <mesh filename="package://armbot_description/onshape_to_robot/armbot/2040_t-slot_(1ft).stl"/>        
      </geometry>      
    </collision>    
    <inertial>      
      <origin xyz="0.017088622111945710874 -1.4152895780101679293e-17 -0.0099999999999999811262" rpy="0 0 0"/>      
      <mass value="0.25219173558876550878"/>      
      <inertia ixx="0.0019627392288486663827" ixy="-1.4907188904893410497e-35" ixz="9.9392086646761764561e-21" iyy="5.108623778154473057e-05" iyz="1.4961835250374266937e-35" izz="0.001993243492111585434"/>      
    </inertial>    
  </link>  
  <joint name="Base2040_To_Base_HebiRotor2020" type="fixed">    
    <origin xyz="-0.045701780749862891406 0.062950280607105876807 -0.030500447380542708431" rpy="-1.5959455978986600617e-16 2.2204460492503658359e-16 -2.2204460492754156209e-16"/>    
    <parent link="base_link"/>    
    <child link="2040_t-slot_(1ft)"/>    
    <axis xyz="0 0 1"/>    
    <limit effort="1" velocity="20"/>    
    <joint_properties friction="0.0"/>    
  </joint>  
  <link name="2020_t-slot_(1ft)">    
    <visual>      
      <origin xyz="0.0070879942314911043022 -6.9388939039072283776e-17 -0.010000000000000015821" rpy="-1.570796326794896558 3.258301496747901038e-16 -3.9672648871758138482e-48"/>      
      <geometry>        
        <mesh filename="package://armbot_description/onshape_to_robot/armbot/2020_t-slot_(1ft).stl"/>        
      </geometry>      
      <material name="2020_t-slot_(1ft)_material">        
        <color rgba="0.90196078431372550543 0.90196078431372550543 0.90196078431372550543 1.0"/>        
      </material>      
    </visual>    
    <collision>      
      <origin xyz="0.0070879942314911043022 -6.9388939039072283776e-17 -0.010000000000000015821" rpy="-1.570796326794896558 3.258301496747901038e-16 -3.9672648871758138482e-48"/>      
      <geometry>        
        <mesh filename="package://armbot_description/onshape_to_robot/armbot/2020_t-slot_(1ft).stl"/>        
      </geometry>      
    </collision>    
    <inertial>      
      <origin xyz="0.0070879942314910947612 -7.3320000794387049634e-17 -0.010000000000000003678" rpy="0 0 0"/>      
      <mass value="0.14544346412865538642"/>      
      <inertia ixx="0.0011319123253517623506" ixy="-3.8455009583638106433e-51" ixz="-1.1840847836153069356e-85" iyy="1.1801323089674781378e-05" iyz="1.725804256000801419e-36" izz="0.0011319123253517623506"/>      
    </inertial>    
  </link>  
  <joint name="Base_HebiRotor2020_Base2020" type="fixed">    
    <origin xyz="-0.10151890936643438723 0.062950280607105890684 -0.03050044738054271537" rpy="6.2450045135167458959e-17 1.1107861648536058948e-30 -3.3157838656870728655e-31"/>    
    <parent link="base_link"/>    
    <child link="2020_t-slot_(1ft)"/>    
    <axis xyz="0 0 1"/>    
    <limit effort="1" velocity="20"/>    
    <joint_properties friction="0.0"/>    
  </joint>  
  <link name="hebi_rotor_disc_">    
    <visual>      
      <origin xyz="0 0 -0.016049999999999998296" rpy="-1.570796326794896558 -1.1826740086016405326e-42 -1.3866695645463571893e-32"/>      
      <geometry>        
        <mesh filename="package://armbot_description/onshape_to_robot/armbot/hebi_rotor_disc_.stl"/>        
      </geometry>      
      <material name="hebi_rotor_disc__material">        
        <color rgba="0.79607843137254896693 0.82352941176470584317 0.9372549019607843146 1.0"/>        
      </material>      
    </visual>    
    <collision>      
      <origin xyz="0 0 -0.016049999999999998296" rpy="-1.570796326794896558 -1.1826740086016405326e-42 -1.3866695645463571893e-32"/>      
      <geometry>        
        <mesh filename="package://armbot_description/onshape_to_robot/armbot/hebi_rotor_disc_.stl"/>        
      </geometry>      
    </collision>    
    <inertial>      
      <origin xyz="0 0 0" rpy="0 0 0"/>      
      <mass value="0"/>      
      <inertia ixx="0" ixy="0" ixz="0" iyy="0" iyz="0" izz="0"/>      
    </inertial>    
  </link>  
  <link name="hebi_stator_">    
    <visual>      
      <origin xyz="0 0 -0.0099999999999999984734" rpy="-1.57079632679489678 8.2107331894046981293e-48 -1.3911062679113435974e-48"/>      
      <geometry>        
        <mesh filename="package://armbot_description/onshape_to_robot/armbot/hebi_stator_.stl"/>        
      </geometry>      
      <material name="hebi_stator__material">        
        <color rgba="0.79607843137254896693 0.82352941176470584317 0.9372549019607843146 1.0"/>        
      </material>      
    </visual>    
    <collision>      
      <origin xyz="0 0 -0.0099999999999999984734" rpy="-1.57079632679489678 8.2107331894046981293e-48 -1.3911062679113435974e-48"/>      
      <geometry>        
        <mesh filename="package://armbot_description/onshape_to_robot/armbot/hebi_stator_.stl"/>        
      </geometry>      
    </collision>    
    <inertial>      
      <origin xyz="0 0 0" rpy="0 0 0"/>      
      <mass value="0"/>      
      <inertia ixx="0" ixy="0" ixz="0" iyy="0" iyz="0" izz="0"/>      
    </inertial>    
  </link>  
  <link name="hebistatornormal2040">    
    <visual>      
      <origin xyz="0.016163453616779399624 0.009999999999999995004 -3.4694469519536141888e-18" rpy="1.570796326794896558 -0 -1.527904422530133894e-32"/>      
      <geometry>        
        <mesh filename="package://armbot_description/onshape_to_robot/armbot/hebistatornormal2040.stl"/>        
      </geometry>      
      <material name="hebistatornormal2040_material">        
        <color rgba="0.78823529411764703401 0.011764705882352941013 0.011764705882352941013 1.0"/>        
      </material>      
    </visual>    
    <collision>      
      <origin xyz="0.016163453616779399624 0.009999999999999995004 -3.4694469519536141888e-18" rpy="1.570796326794896558 -0 -1.527904422530133894e-32"/>      
      <geometry>        
        <mesh filename="package://armbot_description/onshape_to_robot/armbot/hebistatornormal2040.stl"/>        
      </geometry>      
    </collision>    
    <inertial>      
      <origin xyz="0.02633814267204611162 0.010000000134800391544 -0.046566556115122587078" rpy="0 0 0"/>      
      <mass value="0.15651906882669003318"/>      
      <inertia ixx="0.00020929689747815441209" ixy="-5.8518426155922671031e-11" ixz="-1.7895630898721047259e-06" iyy="0.0002279104915185418826" iyz="-6.7009673503899124192e-13" izz="6.2663909985580086245e-05"/>      
    </inertial>    
  </link>  
  <link name="2040_t-slot_(1ft)_2">    
    <visual>      
      <origin xyz="-0.0099267766952966518534 0.019426776695296674169 -0.15240000000000000768" rpy="1.1698359222636737474e-30 5.1358131959370664914e-34 3.796034295538742646e-33"/>      
      <geometry>        
        <mesh filename="package://armbot_description/onshape_to_robot/armbot/2040_t-slot_(1ft).stl"/>        
      </geometry>      
      <material name="2040_t-slot_(1ft)_material">        
        <color rgba="0.90196078431372550543 0.90196078431372550543 0.90196078431372550543 1.0"/>        
      </material>      
    </visual>    
    <collision>      
      <origin xyz="-0.0099267766952966518534 0.019426776695296674169 -0.15240000000000000768" rpy="1.1698359222636737474e-30 5.1358131959370664914e-34 3.796034295538742646e-33"/>      
      <geometry>        
        <mesh filename="package://armbot_description/onshape_to_robot/armbot/2040_t-slot_(1ft).stl"/>        
      </geometry>      
    </collision>    
    <inertial>      
      <origin xyz="-0.0099267766952966275673 0.01992740457575128965 -0.15240000000000000768" rpy="0 0 0"/>      
      <mass value="0.25219173558876550878"/>      
      <inertia ixx="0.001993243492111585434" ixy="2.8525892756834142768e-34" ixz="-1.4195112892829248847e-35" iyy="0.0019627392288486663827" iyz="2.2960828559423262435e-33" izz="5.108623778154473057e-05"/>      
    </inertial>    
  </link>  
  <link name="hebistatorrightangle2040">    
    <visual>      
      <origin xyz="-0.020000000000000003886 0.0022247999999999990006 2.7755575615628913511e-17" rpy="-5.1358132142678020278e-34 1.169835922264012161e-30 -1.4148211990240243682e-31"/>      
      <geometry>        
        <mesh filename="package://armbot_description/onshape_to_robot/armbot/hebistatorrightangle2040.stl"/>        
      </geometry>      
      <material name="hebistatorrightangle2040_material">        
        <color rgba="0.97254901960784312376 0.78039215686274510109 0.82352941176470584317 1.0"/>        
      </material>      
    </visual>    
    <collision>      
      <origin xyz="-0.020000000000000003886 0.0022247999999999990006 2.7755575615628913511e-17" rpy="-5.1358132142678020278e-34 1.169835922264012161e-30 -1.4148211990240243682e-31"/>      
      <geometry>        
        <mesh filename="package://armbot_description/onshape_to_robot/armbot/hebistatorrightangle2040.stl"/>        
      </geometry>      
    </collision>    
    <inertial>      
      <origin xyz="-0.018421103655170835423 0.0034889930474717263317 2.7246994144790953849e-17" rpy="0 0 0"/>      
      <mass value="0.026450088103838233222"/>      
      <inertia ixx="2.5671961898538429701e-05" ixy="-4.5967177282339475176e-10" ixz="-3.0031982987756798525e-35" iyy="2.9117912025295751956e-05" iyz="-9.5705729368624169215e-37" izz="3.656094923152486188e-06"/>      
    </inertial>    
  </link>  
  <link name="hebi_stator__2">    
    <visual>      
      <origin xyz="0.011999999999999998515 -0.023999999999999993561 -0.014999999999999999445" rpy="1.570796326794896558 1.0703707778394610625e-31 -1.3865488122951318568e-30"/>      
      <geometry>        
        <mesh filename="package://armbot_description/onshape_to_robot/armbot/hebi_stator_.stl"/>        
      </geometry>      
      <material name="hebi_stator__material">        
        <color rgba="0.79607843137254896693 0.82352941176470584317 0.9372549019607843146 1.0"/>        
      </material>      
    </visual>    
    <collision>      
      <origin xyz="0.011999999999999998515 -0.023999999999999993561 -0.014999999999999999445" rpy="1.570796326794896558 1.0703707778394610625e-31 -1.3865488122951318568e-30"/>      
      <geometry>        
        <mesh filename="package://armbot_description/onshape_to_robot/armbot/hebi_stator_.stl"/>        
      </geometry>      
    </collision>    
    <inertial>      
      <origin xyz="0 0 0" rpy="0 0 0"/>      
      <mass value="0"/>      
      <inertia ixx="0" ixy="0" ixz="0" iyy="0" iyz="0" izz="0"/>      
    </inertial>    
  </link>  
  <link name="hebi_rotor_disc__2">    
    <visual>      
      <origin xyz="0 -2.7755575615628913511e-17 0.009999999999999995004" rpy="1.570796326794896558 2.5621933856167601622e-33 1.2703590903910827914e-33"/>      
      <geometry>        
        <mesh filename="package://armbot_description/onshape_to_robot/armbot/hebi_rotor_disc_.stl"/>        
      </geometry>      
      <material name="hebi_rotor_disc__material">        
        <color rgba="0.79607843137254896693 0.82352941176470584317 0.9372549019607843146 1.0"/>        
      </material>      
    </visual>    
    <collision>      
      <origin xyz="0 -2.7755575615628913511e-17 0.009999999999999995004" rpy="1.570796326794896558 2.5621933856167601622e-33 1.2703590903910827914e-33"/>      
      <geometry>        
        <mesh filename="package://armbot_description/onshape_to_robot/armbot/hebi_rotor_disc_.stl"/>        
      </geometry>      
    </collision>    
    <inertial>      
      <origin xyz="0 0 0" rpy="0 0 0"/>      
      <mass value="0"/>      
      <inertia ixx="0" ixy="0" ixz="0" iyy="0" iyz="0" izz="0"/>      
    </inertial>    
  </link>  
  <link name="hebirotor2020">    
    <visual>      
      <origin xyz="-0.016167891820442998468 -0.0066969600627778680391 -0.00030000000000000859313" rpy="-3.141592653589793116 2.9656028911684314104e-33 1.2703590903616555236e-33"/>      
      <geometry>        
        <mesh filename="package://armbot_description/onshape_to_robot/armbot/hebirotor2020.stl"/>        
      </geometry>      
      <material name="hebirotor2020_material">        
        <color rgba="0.97254901960784312376 0.78039215686274510109 0.82352941176470584317 1.0"/>        
      </material>      
    </visual>    
    <collision>      
      <origin xyz="-0.016167891820442998468 -0.0066969600627778680391 -0.00030000000000000859313" rpy="-3.141592653589793116 2.9656028911684314104e-33 1.2703590903616555236e-33"/>      
      <geometry>        
        <mesh filename="package://armbot_description/onshape_to_robot/armbot/hebirotor2020.stl"/>        
      </geometry>      
    </collision>    
    <inertial>      
      <origin xyz="-0.016166420745930366876 -0.0066967930656155975205 -0.0098286918188678525088" rpy="0 0 0"/>      
      <mass value="0.10897536745364015676"/>      
      <inertia ixx="2.099532569815209092e-05" ixy="7.1610659884281462033e-10" ixz="-5.0057125776953104015e-10" iyy="0.00033109911054739839297" iyz="-5.8223854086779345631e-11" izz="0.00034907978339312946978"/>      
    </inertial>    
  </link>  
  <link name="2020_t-slot_(1ft)_2">    
    <visual>      
      <origin xyz="-0.00708799423149111818 -4.1633363423443370266e-17 -0.010000000000000036637" rpy="1.570796326794896558 1.570796326794896558 0"/>      
      <geometry>        
        <mesh filename="package://armbot_description/onshape_to_robot/armbot/2020_t-slot_(1ft).stl"/>        
      </geometry>      
      <material name="2020_t-slot_(1ft)_material">        
        <color rgba="0.90196078431372550543 0.90196078431372550543 0.90196078431372550543 1.0"/>        
      </material>      
    </visual>    
    <collision>      
      <origin xyz="-0.00708799423149111818 -4.1633363423443370266e-17 -0.010000000000000036637" rpy="1.570796326794896558 1.570796326794896558 0"/>      
      <geometry>        
        <mesh filename="package://armbot_description/onshape_to_robot/armbot/2020_t-slot_(1ft).stl"/>        
      </geometry>      
    </collision>    
    <inertial>      
      <origin xyz="-0.0070879942314911303231 -3.7702301668128604408e-17 -0.010000000000000026229" rpy="0 0 0"/>      
      <mass value="0.14544346412865538642"/>      
      <inertia ixx="0.0011319123253517623506" ixy="6.6917180800567285326e-36" ixz="-2.179736599627159151e-35" iyy="1.1801323089674781378e-05" iyz="7.4713419052576316191e-37" izz="0.0011319123253517623506"/>      
    </inertial>    
  </link>  
  <link name="dynamount2020">    
    <visual>      
      <origin xyz="0.023843291201925909117 -1.7021168055186830514e-05 -0.012500000000000011102" rpy="1.570796326794896558 -1.7915142111382551394e-32 -7.6221545423522278401e-33"/>      
      <geometry>        
        <mesh filename="package://armbot_description/onshape_to_robot/armbot/dynamount2020.stl"/>        
      </geometry>      
      <material name="dynamount2020_material">        
        <color rgba="0.08627450980392156743 0.31764705882352939348 0.69019607843137253944 1.0"/>        
      </material>      
    </visual>    
    <collision>      
      <origin xyz="0.023843291201925909117 -1.7021168055186830514e-05 -0.012500000000000011102" rpy="1.570796326794896558 -1.7915142111382551394e-32 -7.6221545423522278401e-33"/>      
      <geometry>        
        <mesh filename="package://armbot_description/onshape_to_robot/armbot/dynamount2020.stl"/>        
      </geometry>      
    </collision>    
    <inertial>      
      <origin xyz="0.0066512139609104826976 2.4378127191396239113e-06 -0.0042091105877174357641" rpy="0 0 0"/>      
      <mass value="0.00656743569264333759"/>      
      <inertia ixx="2.8707760317925084672e-07" ixy="7.5996646431139962628e-10" ixz="9.1652725861714266807e-08" iyy="1.1208584748380474788e-06" iyz="3.0603079134551915776e-11" izz="1.338396620352668297e-06"/>      
    </inertial>    
  </link>  
  <link name="dc11_a01_horn_ref">    
    <visual>      
      <origin xyz="0.0079999999999999793499 0 -0.0034999999999999892308" rpy="1.570796326794896558 7.0324022592538482189e-32 3.5707495841849382358e-32"/>      
      <geometry>        
        <mesh filename="package://armbot_description/onshape_to_robot/armbot/dc11_a01_horn_ref.stl"/>        
      </geometry>      
      <material name="dc11_a01_horn_ref_material">        
        <color rgba="0.24313725490196078094 0.24313725490196078094 0.24313725490196078094 1.0"/>        
      </material>      
    </visual>    
    <collision>      
      <origin xyz="0.0079999999999999793499 0 -0.0034999999999999892308" rpy="1.570796326794896558 7.0324022592538482189e-32 3.5707495841849382358e-32"/>      
      <geometry>        
        <mesh filename="package://armbot_description/onshape_to_robot/armbot/dc11_a01_horn_ref.stl"/>        
      </geometry>      
    </collision>    
    <inertial>      
      <origin xyz="0 0 0" rpy="0 0 0"/>      
      <mass value="0"/>      
      <inertia ixx="0" ixy="0" ixz="0" iyy="0" iyz="0" izz="0"/>      
    </inertial>    
  </link>  
  <link name="dc14_a01_ref">    
    <visual>      
      <origin xyz="0 -0.011999999999999982903 -0.019000000000000002998" rpy="0 -1.982503110298479081e-32 0"/>      
      <geometry>        
        <mesh filename="package://armbot_description/onshape_to_robot/armbot/dc14_a01_ref.stl"/>        
      </geometry>      
      <material name="dc14_a01_ref_material">        
        <color rgba="0.22352941176470589313 0.21960784313725489891 0.21960784313725489891 1.0"/>        
      </material>      
    </visual>    
    <collision>      
      <origin xyz="0 -0.011999999999999982903 -0.019000000000000002998" rpy="0 -1.982503110298479081e-32 0"/>      
      <geometry>        
        <mesh filename="package://armbot_description/onshape_to_robot/armbot/dc14_a01_ref.stl"/>        
      </geometry>      
    </collision>    
    <inertial>      
      <origin xyz="0 0 0" rpy="0 0 0"/>      
      <mass value="0"/>      
      <inertia ixx="0" ixy="0" ixz="0" iyy="0" iyz="0" izz="0"/>      
    </inertial>    
  </link>  
  <link name="dc11_a01_horn_ref_2">    
    <visual>      
      <origin xyz="0 -2.7755575615628913511e-17 -0.0035000000000000031086" rpy="1.570796326794896558 -6.3683186095544187119e-33 7.58586795841104892e-31"/>      
      <geometry>        
        <mesh filename="package://armbot_description/onshape_to_robot/armbot/dc11_a01_horn_ref.stl"/>        
      </geometry>      
      <material name="dc11_a01_horn_ref_material">        
        <color rgba="0.24313725490196078094 0.24313725490196078094 0.24313725490196078094 1.0"/>        
      </material>      
    </visual>    
    <collision>      
      <origin xyz="0 -2.7755575615628913511e-17 -0.0035000000000000031086" rpy="1.570796326794896558 -6.3683186095544187119e-33 7.58586795841104892e-31"/>      
      <geometry>        
        <mesh filename="package://armbot_description/onshape_to_robot/armbot/dc11_a01_horn_ref.stl"/>        
      </geometry>      
    </collision>    
    <inertial>      
      <origin xyz="0 0 0" rpy="0 0 0"/>      
      <mass value="0"/>      
      <inertia ixx="0" ixy="0" ixz="0" iyy="0" iyz="0" izz="0"/>      
    </inertial>    
  </link>  
  <joint name="DynaRotor_To_Dynamixel_J3" type="revolute">    
    <origin xyz="0.018999999999999961364 -0.023999999999999993561 -0.019000000000000016875" rpy="3.141592653589793116 -1.5707963267948374941 0"/>    
    <parent link="dc14_a01_ref"/>    
    <child link="dc11_a01_horn_ref_2"/>    
    <axis xyz="0 0 1"/>    
    <limit effort="1" velocity="20"/>    
    <joint_properties friction="0.0"/>    
  </joint>  
  <joint name="DynaRotor_To_Dynamixel_J2" type="revolute">    
    <origin xyz="0.0080000000000000071054 0 0.0002500000247140227172" rpy="-2.7386017334164338663e-16 2.8125133897093823624e-16 1.5707963267948947816"/>    
    <parent link="dc11_a01_horn_ref"/>    
    <child link="dc14_a01_ref"/>    
    <axis xyz="0 0 1"/>    
    <limit effort="1" velocity="20"/>    
    <joint_properties friction="0.0"/>    
  </joint>  
  <joint name="DynaRotor_to_DynaMount" type="fixed">    
    <origin xyz="0.023843291201925853606 0.0079829788319448480305 -0.0089999999999999941158" rpy="-3.7651531049911954153e-31 6.0006654072136856761e-16 -1.5707963267948976682"/>    
    <parent link="dynamount2020"/>    
    <child link="dc11_a01_horn_ref"/>    
    <axis xyz="0 0 1"/>    
    <limit effort="1" velocity="20"/>    
    <joint_properties friction="0.0"/>    
  </joint>  
  <joint name="DynaMount_To_2020" type="fixed">    
    <origin xyz="-0.0068209999999999937348 0.13839999999999996749 -2.7755575615628913511e-17" rpy="-3.1415926535897926719 4.3984719981197447131e-31 1.570796326794896558"/>    
    <parent link="2020_t-slot_(1ft)_2"/>    
    <child link="dynamount2020"/>    
    <axis xyz="0 0 1"/>    
    <limit effort="1" velocity="20"/>    
    <joint_properties friction="0.0"/>    
  </joint>  
  <joint name="2020_To_HebiRotor2020" type="fixed">    
    <origin xyz="-0.1255910324971127312 0.00030303993722216593376 -0.015999999999999972577" rpy="-1.005443759244913916e-15 -9.0014264550852477233e-16 1.570796326794896558"/>    
    <parent link="hebirotor2020"/>    
    <child link="2020_t-slot_(1ft)_2"/>    
    <axis xyz="0 0 1"/>    
    <limit effort="1" velocity="20"/>    
    <joint_properties friction="0.0"/>    
  </joint>  
  <joint name="HebiRotor2020_to_J1_Hebi" type="fixed">    
    <origin xyz="-0.016167891818947597443 -0.006696960066388979449 -0.0060499999999999998224" rpy="-1.1102230246249354129e-16 -1.1858535512172089174e-30 3.141592653589793116"/>    
    <parent link="hebi_rotor_disc__2"/>    
    <child link="hebirotor2020"/>    
    <axis xyz="0 0 1"/>    
    <limit effort="1" velocity="20"/>    
    <joint_properties friction="0.0"/>    
  </joint>  
  <joint name="Hebi_Rotor_J1" type="revolute">    
    <origin xyz="0.011999999999999998515 -0.023999999999999993561 -0.025000000000000008327" rpy="5.9494768527395596694e-15 3.5527136788003975886e-15 -3.1415926535897784611"/>    
    <parent link="hebi_stator__2"/>    
    <child link="hebi_rotor_disc__2"/>    
    <axis xyz="0 0 1"/>    
    <limit effort="1" velocity="20"/>    
    <joint_properties friction="0.0"/>    
  </joint>  
  <joint name="Hebi_J1_Stator_To_HebiStatorRightAngle" type="fixed">    
    <origin xyz="-0.010000000000000008882 0.0070000000000000062172 -0.02399999999999993805" rpy="-1.57079632679489678 -2.6180406973397104759e-16 -3.141592653589793116"/>    
    <parent link="hebistatorrightangle2040"/>    
    <child link="hebi_stator__2"/>    
    <axis xyz="0 0 1"/>    
    <limit effort="1" velocity="20"/>    
    <joint_properties friction="0.0"/>    
  </joint>  
  <joint name="HebiStatorRightAngle_To_2040" type="fixed">    
    <origin xyz="7.3223304703343150557e-05 0.00017677669529668135762 -0.15239999999999995217" rpy="5.1275445258044345651e-29 -8.2964949403881295039e-30 -1.570796326794896558"/>    
    <parent link="2040_t-slot_(1ft)_2"/>    
    <child link="hebistatorrightangle2040"/>    
    <axis xyz="0 0 1"/>    
    <limit effort="1" velocity="20"/>    
    <joint_properties friction="0.0"/>    
  </joint>  
  <joint name="2040_To_HebiStatorNormal" type="fixed">    
    <origin xyz="0.006096325915182342764 8.2872298402925093086e-05 -0.010000000000000001943" rpy="1.4054351759203417495e-14 -7.8886090522099323821e-31 -1.57079632679489678"/>    
    <parent link="hebistatornormal2040"/>    
    <child link="2040_t-slot_(1ft)_2"/>    
    <axis xyz="0 0 1"/>    
    <limit effort="1" velocity="20"/>    
    <joint_properties friction="0.0"/>    
  </joint>  
  <joint name="Hebi_Base_Stator_To_HebiStatorNormal" type="fixed">    
    <origin xyz="-0.026000000000000005745 -0.010000000000000008882 -0.025000000000000001388" rpy="-2.1279274638652611185e-16 -3.8857805861928249373e-16 3.3306690738810498261e-16"/>    
    <parent link="hebi_stator_"/>    
    <child link="hebistatornormal2040"/>    
    <axis xyz="0 0 1"/>    
    <limit effort="1" velocity="20"/>    
    <joint_properties friction="0.0"/>    
  </joint>  
  <joint name="Hebi_Rotor_Base" type="revolute">    
    <origin xyz="-2.2204460492987806949e-18 0 -0.006049999999999713593" rpy="4.4408920985003254085e-16 -2.2204460492510994766e-16 -2.2204460492878653251e-16"/>    
    <parent link="hebi_rotor_disc_"/>    
    <child link="hebi_stator_"/>    
    <axis xyz="0 0 1"/>    
    <limit effort="1" velocity="20"/>    
    <joint_properties friction="0.0"/>    
  </joint>  
  <joint name="HebiRotor2020_To_HebiBase" type="fixed">    
    <origin xyz="-1.4954045890469558738e-12 0.062950280607105862929 -0.014500447380542770548" rpy="-3.141592653589793116 -2.2204460492511265937e-16 -2.2204460492878865258e-16"/>    
    <parent link="base_link"/>    
    <child link="hebi_rotor_disc_"/>    
    <axis xyz="0 0 1"/>    
    <limit effort="1" velocity="20"/>    
    <joint_properties friction="0.0"/>    
  </joint>  
</robot>